[2024-07-21T23:42:36.575+0000] {local_task_job_runner.py:120} INFO - ::group::Pre task execution logs
[2024-07-21T23:42:36.607+0000] {taskinstance.py:2076} INFO - Dependencies all met for dep_context=non-requeueable deps ti=<TaskInstance: our_first_dag.first_task manual__2024-07-21T23:42:35.204485+00:00 [queued]>
[2024-07-21T23:42:36.618+0000] {taskinstance.py:2076} INFO - Dependencies all met for dep_context=requeueable deps ti=<TaskInstance: our_first_dag.first_task manual__2024-07-21T23:42:35.204485+00:00 [queued]>
[2024-07-21T23:42:36.619+0000] {taskinstance.py:2306} INFO - Starting attempt 1 of 6
[2024-07-21T23:42:36.638+0000] {taskinstance.py:2330} INFO - Executing <Task(BashOperator): first_task> on 2024-07-21 23:42:35.204485+00:00
[2024-07-21T23:42:36.644+0000] {warnings.py:110} WARNING - /home/***/.local/lib/python3.12/site-packages/***/task/task_runner/standard_task_runner.py:61: DeprecationWarning: This process (pid=362) is multi-threaded, use of fork() may lead to deadlocks in the child.
  pid = os.fork()

[2024-07-21T23:42:36.646+0000] {standard_task_runner.py:63} INFO - Started process 363 to run task
[2024-07-21T23:42:36.646+0000] {standard_task_runner.py:90} INFO - Running: ['***', 'tasks', 'run', 'our_first_dag', 'first_task', 'manual__2024-07-21T23:42:35.204485+00:00', '--job-id', '12', '--raw', '--subdir', 'DAGS_FOLDER/our_first_dag.py', '--cfg-path', '/tmp/tmpmdkbzdym']
[2024-07-21T23:42:36.647+0000] {standard_task_runner.py:91} INFO - Job 12: Subtask first_task
[2024-07-21T23:42:36.701+0000] {task_command.py:426} INFO - Running <TaskInstance: our_first_dag.first_task manual__2024-07-21T23:42:35.204485+00:00 [running]> on host eefce25a52e3
[2024-07-21T23:42:36.807+0000] {taskinstance.py:2648} INFO - Exporting env vars: AIRFLOW_CTX_DAG_OWNER='***' AIRFLOW_CTX_DAG_ID='our_first_dag' AIRFLOW_CTX_TASK_ID='first_task' AIRFLOW_CTX_EXECUTION_DATE='2024-07-21T23:42:35.204485+00:00' AIRFLOW_CTX_TRY_NUMBER='1' AIRFLOW_CTX_DAG_RUN_ID='manual__2024-07-21T23:42:35.204485+00:00'
[2024-07-21T23:42:36.809+0000] {taskinstance.py:430} INFO - ::endgroup::
[2024-07-21T23:42:36.824+0000] {subprocess.py:63} INFO - Tmp dir root location: /tmp
[2024-07-21T23:42:36.825+0000] {subprocess.py:75} INFO - Running command: ['/usr/bin/bash', '-c', 'ech0 Hello World, this is the first task to be done']
[2024-07-21T23:42:36.835+0000] {subprocess.py:86} INFO - Output:
[2024-07-21T23:42:36.838+0000] {subprocess.py:93} INFO - /usr/bin/bash: line 1: ech0: command not found
[2024-07-21T23:42:36.838+0000] {subprocess.py:97} INFO - Command exited with return code 127
[2024-07-21T23:42:36.839+0000] {taskinstance.py:441} INFO - ::group::Post task execution logs
[2024-07-21T23:42:36.851+0000] {taskinstance.py:2905} ERROR - Task failed with exception
Traceback (most recent call last):
  File "/home/airflow/.local/lib/python3.12/site-packages/airflow/models/taskinstance.py", line 465, in _execute_task
    result = _execute_callable(context=context, **execute_callable_kwargs)
             ^^^^^^^^^^^^^^^^^^^^^^^^^^^^^^^^^^^^^^^^^^^^^^^^^^^^^^^^^^^^^
  File "/home/airflow/.local/lib/python3.12/site-packages/airflow/models/taskinstance.py", line 432, in _execute_callable
    return execute_callable(context=context, **execute_callable_kwargs)
           ^^^^^^^^^^^^^^^^^^^^^^^^^^^^^^^^^^^^^^^^^^^^^^^^^^^^^^^^^^^^
  File "/home/airflow/.local/lib/python3.12/site-packages/airflow/models/baseoperator.py", line 400, in wrapper
    return func(self, *args, **kwargs)
           ^^^^^^^^^^^^^^^^^^^^^^^^^^^
  File "/home/airflow/.local/lib/python3.12/site-packages/airflow/operators/bash.py", line 243, in execute
    raise AirflowException(
airflow.exceptions.AirflowException: Bash command failed. The command returned a non-zero exit code 127.
[2024-07-21T23:42:36.856+0000] {taskinstance.py:1206} INFO - Marking task as UP_FOR_RETRY. dag_id=our_first_dag, task_id=first_task, run_id=manual__2024-07-21T23:42:35.204485+00:00, execution_date=20240721T234235, start_date=20240721T234236, end_date=20240721T234236
[2024-07-21T23:42:36.873+0000] {standard_task_runner.py:110} ERROR - Failed to execute job 12 for task first_task (Bash command failed. The command returned a non-zero exit code 127.; 363)
[2024-07-21T23:42:36.900+0000] {local_task_job_runner.py:240} INFO - Task exited with return code 1
[2024-07-21T23:42:36.918+0000] {taskinstance.py:3498} INFO - 0 downstream tasks scheduled from follow-on schedule check
[2024-07-21T23:42:36.922+0000] {local_task_job_runner.py:222} INFO - ::endgroup::
