[2024-07-21T23:37:02.349+0000] {local_task_job_runner.py:120} INFO - ::group::Pre task execution logs
[2024-07-21T23:37:02.372+0000] {taskinstance.py:2076} INFO - Dependencies all met for dep_context=non-requeueable deps ti=<TaskInstance: our_first_dag.first_task manual__2024-07-21T23:34:57.300350+00:00 [queued]>
[2024-07-21T23:37:02.380+0000] {taskinstance.py:2076} INFO - Dependencies all met for dep_context=requeueable deps ti=<TaskInstance: our_first_dag.first_task manual__2024-07-21T23:34:57.300350+00:00 [queued]>
[2024-07-21T23:37:02.381+0000] {taskinstance.py:2306} INFO - Starting attempt 2 of 6
[2024-07-21T23:37:02.398+0000] {taskinstance.py:2330} INFO - Executing <Task(BashOperator): first_task> on 2024-07-21 23:34:57.300350+00:00
[2024-07-21T23:37:02.404+0000] {warnings.py:110} WARNING - /home/***/.local/lib/python3.12/site-packages/***/task/task_runner/standard_task_runner.py:61: DeprecationWarning: This process (pid=277) is multi-threaded, use of fork() may lead to deadlocks in the child.
  pid = os.fork()

[2024-07-21T23:37:02.405+0000] {standard_task_runner.py:63} INFO - Started process 278 to run task
[2024-07-21T23:37:02.405+0000] {standard_task_runner.py:90} INFO - Running: ['***', 'tasks', 'run', 'our_first_dag', 'first_task', 'manual__2024-07-21T23:34:57.300350+00:00', '--job-id', '7', '--raw', '--subdir', 'DAGS_FOLDER/our_first_dag.py', '--cfg-path', '/tmp/tmpdgs69hp2']
[2024-07-21T23:37:02.407+0000] {standard_task_runner.py:91} INFO - Job 7: Subtask first_task
[2024-07-21T23:37:02.459+0000] {task_command.py:426} INFO - Running <TaskInstance: our_first_dag.first_task manual__2024-07-21T23:34:57.300350+00:00 [running]> on host eefce25a52e3
[2024-07-21T23:37:02.558+0000] {taskinstance.py:2648} INFO - Exporting env vars: AIRFLOW_CTX_DAG_OWNER='***' AIRFLOW_CTX_DAG_ID='our_first_dag' AIRFLOW_CTX_TASK_ID='first_task' AIRFLOW_CTX_EXECUTION_DATE='2024-07-21T23:34:57.300350+00:00' AIRFLOW_CTX_TRY_NUMBER='2' AIRFLOW_CTX_DAG_RUN_ID='manual__2024-07-21T23:34:57.300350+00:00'
[2024-07-21T23:37:02.559+0000] {taskinstance.py:430} INFO - ::endgroup::
[2024-07-21T23:37:02.577+0000] {subprocess.py:63} INFO - Tmp dir root location: /tmp
[2024-07-21T23:37:02.578+0000] {subprocess.py:75} INFO - Running command: ['/usr/bin/bash', '-c', 'ech0 Hello World, this is the first task to be done']
[2024-07-21T23:37:02.589+0000] {subprocess.py:86} INFO - Output:
[2024-07-21T23:37:02.591+0000] {subprocess.py:93} INFO - /usr/bin/bash: line 1: ech0: command not found
[2024-07-21T23:37:02.591+0000] {subprocess.py:97} INFO - Command exited with return code 127
[2024-07-21T23:37:02.592+0000] {taskinstance.py:441} INFO - ::group::Post task execution logs
[2024-07-21T23:37:02.604+0000] {taskinstance.py:2905} ERROR - Task failed with exception
Traceback (most recent call last):
  File "/home/airflow/.local/lib/python3.12/site-packages/airflow/models/taskinstance.py", line 465, in _execute_task
    result = _execute_callable(context=context, **execute_callable_kwargs)
             ^^^^^^^^^^^^^^^^^^^^^^^^^^^^^^^^^^^^^^^^^^^^^^^^^^^^^^^^^^^^^
  File "/home/airflow/.local/lib/python3.12/site-packages/airflow/models/taskinstance.py", line 432, in _execute_callable
    return execute_callable(context=context, **execute_callable_kwargs)
           ^^^^^^^^^^^^^^^^^^^^^^^^^^^^^^^^^^^^^^^^^^^^^^^^^^^^^^^^^^^^
  File "/home/airflow/.local/lib/python3.12/site-packages/airflow/models/baseoperator.py", line 400, in wrapper
    return func(self, *args, **kwargs)
           ^^^^^^^^^^^^^^^^^^^^^^^^^^^
  File "/home/airflow/.local/lib/python3.12/site-packages/airflow/operators/bash.py", line 243, in execute
    raise AirflowException(
airflow.exceptions.AirflowException: Bash command failed. The command returned a non-zero exit code 127.
[2024-07-21T23:37:02.609+0000] {taskinstance.py:1206} INFO - Marking task as UP_FOR_RETRY. dag_id=our_first_dag, task_id=first_task, run_id=manual__2024-07-21T23:34:57.300350+00:00, execution_date=20240721T233457, start_date=20240721T233702, end_date=20240721T233702
[2024-07-21T23:37:02.628+0000] {standard_task_runner.py:110} ERROR - Failed to execute job 7 for task first_task (Bash command failed. The command returned a non-zero exit code 127.; 278)
[2024-07-21T23:37:02.660+0000] {local_task_job_runner.py:240} INFO - Task exited with return code 1
[2024-07-21T23:37:02.680+0000] {taskinstance.py:3498} INFO - 0 downstream tasks scheduled from follow-on schedule check
[2024-07-21T23:37:02.685+0000] {local_task_job_runner.py:222} INFO - ::endgroup::
