[2024-07-21T23:40:41.003+0000] {local_task_job_runner.py:120} INFO - ::group::Pre task execution logs
[2024-07-21T23:40:41.043+0000] {taskinstance.py:2076} INFO - Dependencies all met for dep_context=non-requeueable deps ti=<TaskInstance: our_first_dag.first_task manual__2024-07-21T23:40:39.049372+00:00 [queued]>
[2024-07-21T23:40:41.055+0000] {taskinstance.py:2076} INFO - Dependencies all met for dep_context=requeueable deps ti=<TaskInstance: our_first_dag.first_task manual__2024-07-21T23:40:39.049372+00:00 [queued]>
[2024-07-21T23:40:41.056+0000] {taskinstance.py:2306} INFO - Starting attempt 1 of 6
[2024-07-21T23:40:41.076+0000] {taskinstance.py:2330} INFO - Executing <Task(BashOperator): first_task> on 2024-07-21 23:40:39.049372+00:00
[2024-07-21T23:40:41.083+0000] {warnings.py:110} WARNING - /home/***/.local/lib/python3.12/site-packages/***/task/task_runner/standard_task_runner.py:61: DeprecationWarning: This process (pid=335) is multi-threaded, use of fork() may lead to deadlocks in the child.
  pid = os.fork()

[2024-07-21T23:40:41.085+0000] {standard_task_runner.py:63} INFO - Started process 337 to run task
[2024-07-21T23:40:41.085+0000] {standard_task_runner.py:90} INFO - Running: ['***', 'tasks', 'run', 'our_first_dag', 'first_task', 'manual__2024-07-21T23:40:39.049372+00:00', '--job-id', '10', '--raw', '--subdir', 'DAGS_FOLDER/our_first_dag.py', '--cfg-path', '/tmp/tmpb8v0v1hr']
[2024-07-21T23:40:41.087+0000] {standard_task_runner.py:91} INFO - Job 10: Subtask first_task
[2024-07-21T23:40:41.160+0000] {task_command.py:426} INFO - Running <TaskInstance: our_first_dag.first_task manual__2024-07-21T23:40:39.049372+00:00 [running]> on host eefce25a52e3
[2024-07-21T23:40:41.288+0000] {taskinstance.py:2648} INFO - Exporting env vars: AIRFLOW_CTX_DAG_OWNER='***' AIRFLOW_CTX_DAG_ID='our_first_dag' AIRFLOW_CTX_TASK_ID='first_task' AIRFLOW_CTX_EXECUTION_DATE='2024-07-21T23:40:39.049372+00:00' AIRFLOW_CTX_TRY_NUMBER='1' AIRFLOW_CTX_DAG_RUN_ID='manual__2024-07-21T23:40:39.049372+00:00'
[2024-07-21T23:40:41.290+0000] {taskinstance.py:430} INFO - ::endgroup::
[2024-07-21T23:40:41.312+0000] {subprocess.py:63} INFO - Tmp dir root location: /tmp
[2024-07-21T23:40:41.314+0000] {subprocess.py:75} INFO - Running command: ['/usr/bin/bash', '-c', 'ech0 Hello World, this is the first task to be done']
[2024-07-21T23:40:41.327+0000] {subprocess.py:86} INFO - Output:
[2024-07-21T23:40:41.329+0000] {subprocess.py:93} INFO - /usr/bin/bash: line 1: ech0: command not found
[2024-07-21T23:40:41.331+0000] {subprocess.py:97} INFO - Command exited with return code 127
[2024-07-21T23:40:41.333+0000] {taskinstance.py:441} INFO - ::group::Post task execution logs
[2024-07-21T23:40:41.349+0000] {taskinstance.py:2905} ERROR - Task failed with exception
Traceback (most recent call last):
  File "/home/airflow/.local/lib/python3.12/site-packages/airflow/models/taskinstance.py", line 465, in _execute_task
    result = _execute_callable(context=context, **execute_callable_kwargs)
             ^^^^^^^^^^^^^^^^^^^^^^^^^^^^^^^^^^^^^^^^^^^^^^^^^^^^^^^^^^^^^
  File "/home/airflow/.local/lib/python3.12/site-packages/airflow/models/taskinstance.py", line 432, in _execute_callable
    return execute_callable(context=context, **execute_callable_kwargs)
           ^^^^^^^^^^^^^^^^^^^^^^^^^^^^^^^^^^^^^^^^^^^^^^^^^^^^^^^^^^^^
  File "/home/airflow/.local/lib/python3.12/site-packages/airflow/models/baseoperator.py", line 400, in wrapper
    return func(self, *args, **kwargs)
           ^^^^^^^^^^^^^^^^^^^^^^^^^^^
  File "/home/airflow/.local/lib/python3.12/site-packages/airflow/operators/bash.py", line 243, in execute
    raise AirflowException(
airflow.exceptions.AirflowException: Bash command failed. The command returned a non-zero exit code 127.
[2024-07-21T23:40:41.356+0000] {taskinstance.py:1206} INFO - Marking task as UP_FOR_RETRY. dag_id=our_first_dag, task_id=first_task, run_id=manual__2024-07-21T23:40:39.049372+00:00, execution_date=20240721T234039, start_date=20240721T234041, end_date=20240721T234041
[2024-07-21T23:40:41.378+0000] {standard_task_runner.py:110} ERROR - Failed to execute job 10 for task first_task (Bash command failed. The command returned a non-zero exit code 127.; 337)
[2024-07-21T23:40:41.420+0000] {local_task_job_runner.py:240} INFO - Task exited with return code 1
[2024-07-21T23:40:41.440+0000] {taskinstance.py:3498} INFO - 0 downstream tasks scheduled from follow-on schedule check
[2024-07-21T23:40:41.444+0000] {local_task_job_runner.py:222} INFO - ::endgroup::
