[2024-07-21T23:36:06.868+0000] {local_task_job_runner.py:120} INFO - ::group::Pre task execution logs
[2024-07-21T23:36:06.906+0000] {taskinstance.py:2076} INFO - Dependencies all met for dep_context=non-requeueable deps ti=<TaskInstance: our_first_dag.first_task scheduled__2024-07-20T00:00:00+00:00 [queued]>
[2024-07-21T23:36:06.916+0000] {taskinstance.py:2076} INFO - Dependencies all met for dep_context=requeueable deps ti=<TaskInstance: our_first_dag.first_task scheduled__2024-07-20T00:00:00+00:00 [queued]>
[2024-07-21T23:36:06.917+0000] {taskinstance.py:2306} INFO - Starting attempt 1 of 6
[2024-07-21T23:36:06.940+0000] {taskinstance.py:2330} INFO - Executing <Task(BashOperator): first_task> on 2024-07-20 00:00:00+00:00
[2024-07-21T23:36:06.947+0000] {warnings.py:110} WARNING - /home/***/.local/lib/python3.12/site-packages/***/task/task_runner/standard_task_runner.py:61: DeprecationWarning: This process (pid=261) is multi-threaded, use of fork() may lead to deadlocks in the child.
  pid = os.fork()

[2024-07-21T23:36:06.949+0000] {standard_task_runner.py:63} INFO - Started process 262 to run task
[2024-07-21T23:36:06.948+0000] {standard_task_runner.py:90} INFO - Running: ['***', 'tasks', 'run', 'our_first_dag', 'first_task', 'scheduled__2024-07-20T00:00:00+00:00', '--job-id', '4', '--raw', '--subdir', 'DAGS_FOLDER/our_first_dag.py', '--cfg-path', '/tmp/tmpww9b2x25']
[2024-07-21T23:36:06.950+0000] {standard_task_runner.py:91} INFO - Job 4: Subtask first_task
[2024-07-21T23:36:07.017+0000] {task_command.py:426} INFO - Running <TaskInstance: our_first_dag.first_task scheduled__2024-07-20T00:00:00+00:00 [running]> on host eefce25a52e3
[2024-07-21T23:36:07.112+0000] {taskinstance.py:2648} INFO - Exporting env vars: AIRFLOW_CTX_DAG_OWNER='***' AIRFLOW_CTX_DAG_ID='our_first_dag' AIRFLOW_CTX_TASK_ID='first_task' AIRFLOW_CTX_EXECUTION_DATE='2024-07-20T00:00:00+00:00' AIRFLOW_CTX_TRY_NUMBER='1' AIRFLOW_CTX_DAG_RUN_ID='scheduled__2024-07-20T00:00:00+00:00'
[2024-07-21T23:36:07.113+0000] {taskinstance.py:430} INFO - ::endgroup::
[2024-07-21T23:36:07.130+0000] {subprocess.py:63} INFO - Tmp dir root location: /tmp
[2024-07-21T23:36:07.131+0000] {subprocess.py:75} INFO - Running command: ['/usr/bin/bash', '-c', 'ech0 Hello World, this is the first task to be done']
[2024-07-21T23:36:07.140+0000] {subprocess.py:86} INFO - Output:
[2024-07-21T23:36:07.142+0000] {subprocess.py:93} INFO - /usr/bin/bash: line 1: ech0: command not found
[2024-07-21T23:36:07.142+0000] {subprocess.py:97} INFO - Command exited with return code 127
[2024-07-21T23:36:07.143+0000] {taskinstance.py:441} INFO - ::group::Post task execution logs
[2024-07-21T23:36:07.152+0000] {taskinstance.py:2905} ERROR - Task failed with exception
Traceback (most recent call last):
  File "/home/airflow/.local/lib/python3.12/site-packages/airflow/models/taskinstance.py", line 465, in _execute_task
    result = _execute_callable(context=context, **execute_callable_kwargs)
             ^^^^^^^^^^^^^^^^^^^^^^^^^^^^^^^^^^^^^^^^^^^^^^^^^^^^^^^^^^^^^
  File "/home/airflow/.local/lib/python3.12/site-packages/airflow/models/taskinstance.py", line 432, in _execute_callable
    return execute_callable(context=context, **execute_callable_kwargs)
           ^^^^^^^^^^^^^^^^^^^^^^^^^^^^^^^^^^^^^^^^^^^^^^^^^^^^^^^^^^^^
  File "/home/airflow/.local/lib/python3.12/site-packages/airflow/models/baseoperator.py", line 400, in wrapper
    return func(self, *args, **kwargs)
           ^^^^^^^^^^^^^^^^^^^^^^^^^^^
  File "/home/airflow/.local/lib/python3.12/site-packages/airflow/operators/bash.py", line 243, in execute
    raise AirflowException(
airflow.exceptions.AirflowException: Bash command failed. The command returned a non-zero exit code 127.
[2024-07-21T23:36:07.158+0000] {taskinstance.py:1206} INFO - Marking task as UP_FOR_RETRY. dag_id=our_first_dag, task_id=first_task, run_id=scheduled__2024-07-20T00:00:00+00:00, execution_date=20240720T000000, start_date=20240721T233606, end_date=20240721T233607
[2024-07-21T23:36:07.173+0000] {standard_task_runner.py:110} ERROR - Failed to execute job 4 for task first_task (Bash command failed. The command returned a non-zero exit code 127.; 262)
[2024-07-21T23:36:07.204+0000] {local_task_job_runner.py:240} INFO - Task exited with return code 1
[2024-07-21T23:36:07.224+0000] {taskinstance.py:3498} INFO - 0 downstream tasks scheduled from follow-on schedule check
[2024-07-21T23:36:07.228+0000] {local_task_job_runner.py:222} INFO - ::endgroup::
[2024-07-21T23:38:39.045+0000] {local_task_job_runner.py:120} INFO - ::group::Pre task execution logs
[2024-07-21T23:38:39.091+0000] {taskinstance.py:2076} INFO - Dependencies all met for dep_context=non-requeueable deps ti=<TaskInstance: our_first_dag.first_task scheduled__2024-07-20T00:00:00+00:00 [queued]>
[2024-07-21T23:38:39.110+0000] {taskinstance.py:2076} INFO - Dependencies all met for dep_context=requeueable deps ti=<TaskInstance: our_first_dag.first_task scheduled__2024-07-20T00:00:00+00:00 [queued]>
[2024-07-21T23:38:39.110+0000] {taskinstance.py:2306} INFO - Starting attempt 1 of 6
[2024-07-21T23:38:39.146+0000] {taskinstance.py:2330} INFO - Executing <Task(BashOperator): first_task> on 2024-07-20 00:00:00+00:00
[2024-07-21T23:38:39.158+0000] {warnings.py:110} WARNING - /home/***/.local/lib/python3.12/site-packages/***/task/task_runner/standard_task_runner.py:61: DeprecationWarning: This process (pid=304) is multi-threaded, use of fork() may lead to deadlocks in the child.
  pid = os.fork()

[2024-07-21T23:38:39.160+0000] {standard_task_runner.py:63} INFO - Started process 305 to run task
[2024-07-21T23:38:39.160+0000] {standard_task_runner.py:90} INFO - Running: ['***', 'tasks', 'run', 'our_first_dag', 'first_task', 'scheduled__2024-07-20T00:00:00+00:00', '--job-id', '9', '--raw', '--subdir', 'DAGS_FOLDER/our_first_dag.py', '--cfg-path', '/tmp/tmpwmxvz8ra']
[2024-07-21T23:38:39.162+0000] {standard_task_runner.py:91} INFO - Job 9: Subtask first_task
[2024-07-21T23:38:39.257+0000] {task_command.py:426} INFO - Running <TaskInstance: our_first_dag.first_task scheduled__2024-07-20T00:00:00+00:00 [running]> on host eefce25a52e3
[2024-07-21T23:38:39.460+0000] {taskinstance.py:2648} INFO - Exporting env vars: AIRFLOW_CTX_DAG_OWNER='***' AIRFLOW_CTX_DAG_ID='our_first_dag' AIRFLOW_CTX_TASK_ID='first_task' AIRFLOW_CTX_EXECUTION_DATE='2024-07-20T00:00:00+00:00' AIRFLOW_CTX_TRY_NUMBER='1' AIRFLOW_CTX_DAG_RUN_ID='scheduled__2024-07-20T00:00:00+00:00'
[2024-07-21T23:38:39.462+0000] {taskinstance.py:430} INFO - ::endgroup::
[2024-07-21T23:38:39.510+0000] {subprocess.py:63} INFO - Tmp dir root location: /tmp
[2024-07-21T23:38:39.512+0000] {subprocess.py:75} INFO - Running command: ['/usr/bin/bash', '-c', 'ech0 Hello World, this is the first task to be done']
[2024-07-21T23:38:39.530+0000] {subprocess.py:86} INFO - Output:
[2024-07-21T23:38:39.533+0000] {subprocess.py:93} INFO - /usr/bin/bash: line 1: ech0: command not found
[2024-07-21T23:38:39.538+0000] {subprocess.py:97} INFO - Command exited with return code 127
[2024-07-21T23:38:39.540+0000] {taskinstance.py:441} INFO - ::group::Post task execution logs
[2024-07-21T23:38:39.563+0000] {taskinstance.py:2905} ERROR - Task failed with exception
Traceback (most recent call last):
  File "/home/airflow/.local/lib/python3.12/site-packages/airflow/models/taskinstance.py", line 465, in _execute_task
    result = _execute_callable(context=context, **execute_callable_kwargs)
             ^^^^^^^^^^^^^^^^^^^^^^^^^^^^^^^^^^^^^^^^^^^^^^^^^^^^^^^^^^^^^
  File "/home/airflow/.local/lib/python3.12/site-packages/airflow/models/taskinstance.py", line 432, in _execute_callable
    return execute_callable(context=context, **execute_callable_kwargs)
           ^^^^^^^^^^^^^^^^^^^^^^^^^^^^^^^^^^^^^^^^^^^^^^^^^^^^^^^^^^^^
  File "/home/airflow/.local/lib/python3.12/site-packages/airflow/models/baseoperator.py", line 400, in wrapper
    return func(self, *args, **kwargs)
           ^^^^^^^^^^^^^^^^^^^^^^^^^^^
  File "/home/airflow/.local/lib/python3.12/site-packages/airflow/operators/bash.py", line 243, in execute
    raise AirflowException(
airflow.exceptions.AirflowException: Bash command failed. The command returned a non-zero exit code 127.
[2024-07-21T23:38:39.575+0000] {taskinstance.py:1206} INFO - Marking task as UP_FOR_RETRY. dag_id=our_first_dag, task_id=first_task, run_id=scheduled__2024-07-20T00:00:00+00:00, execution_date=20240720T000000, start_date=20240721T233839, end_date=20240721T233839
[2024-07-21T23:38:39.605+0000] {standard_task_runner.py:110} ERROR - Failed to execute job 9 for task first_task (Bash command failed. The command returned a non-zero exit code 127.; 305)
[2024-07-21T23:38:39.618+0000] {local_task_job_runner.py:240} INFO - Task exited with return code 1
[2024-07-21T23:38:39.655+0000] {taskinstance.py:3498} INFO - 0 downstream tasks scheduled from follow-on schedule check
[2024-07-21T23:38:39.660+0000] {local_task_job_runner.py:222} INFO - ::endgroup::
[2024-07-21T23:42:39.349+0000] {local_task_job_runner.py:120} INFO - ::group::Pre task execution logs
[2024-07-21T23:42:39.386+0000] {taskinstance.py:2076} INFO - Dependencies all met for dep_context=non-requeueable deps ti=<TaskInstance: our_first_dag.first_task scheduled__2024-07-20T00:00:00+00:00 [queued]>
[2024-07-21T23:42:39.398+0000] {taskinstance.py:2076} INFO - Dependencies all met for dep_context=requeueable deps ti=<TaskInstance: our_first_dag.first_task scheduled__2024-07-20T00:00:00+00:00 [queued]>
[2024-07-21T23:42:39.399+0000] {taskinstance.py:2306} INFO - Starting attempt 1 of 6
[2024-07-21T23:42:39.420+0000] {taskinstance.py:2330} INFO - Executing <Task(BashOperator): first_task> on 2024-07-20 00:00:00+00:00
[2024-07-21T23:42:39.437+0000] {warnings.py:110} WARNING - /home/***/.local/lib/python3.12/site-packages/***/task/task_runner/standard_task_runner.py:61: DeprecationWarning: This process (pid=368) is multi-threaded, use of fork() may lead to deadlocks in the child.
  pid = os.fork()

[2024-07-21T23:42:39.442+0000] {standard_task_runner.py:63} INFO - Started process 372 to run task
[2024-07-21T23:42:39.441+0000] {standard_task_runner.py:90} INFO - Running: ['***', 'tasks', 'run', 'our_first_dag', 'first_task', 'scheduled__2024-07-20T00:00:00+00:00', '--job-id', '15', '--raw', '--subdir', 'DAGS_FOLDER/our_first_dag.py', '--cfg-path', '/tmp/tmp5baqwb8l']
[2024-07-21T23:42:39.444+0000] {standard_task_runner.py:91} INFO - Job 15: Subtask first_task
[2024-07-21T23:42:39.518+0000] {task_command.py:426} INFO - Running <TaskInstance: our_first_dag.first_task scheduled__2024-07-20T00:00:00+00:00 [running]> on host eefce25a52e3
[2024-07-21T23:42:39.621+0000] {taskinstance.py:2648} INFO - Exporting env vars: AIRFLOW_CTX_DAG_OWNER='***' AIRFLOW_CTX_DAG_ID='our_first_dag' AIRFLOW_CTX_TASK_ID='first_task' AIRFLOW_CTX_EXECUTION_DATE='2024-07-20T00:00:00+00:00' AIRFLOW_CTX_TRY_NUMBER='1' AIRFLOW_CTX_DAG_RUN_ID='scheduled__2024-07-20T00:00:00+00:00'
[2024-07-21T23:42:39.623+0000] {taskinstance.py:430} INFO - ::endgroup::
[2024-07-21T23:42:39.645+0000] {subprocess.py:63} INFO - Tmp dir root location: /tmp
[2024-07-21T23:42:39.646+0000] {subprocess.py:75} INFO - Running command: ['/usr/bin/bash', '-c', 'ech0 Hello World, this is the first task to be done']
[2024-07-21T23:42:39.656+0000] {subprocess.py:86} INFO - Output:
[2024-07-21T23:42:39.657+0000] {subprocess.py:93} INFO - /usr/bin/bash: line 1: ech0: command not found
[2024-07-21T23:42:39.658+0000] {subprocess.py:97} INFO - Command exited with return code 127
[2024-07-21T23:42:39.659+0000] {taskinstance.py:441} INFO - ::group::Post task execution logs
[2024-07-21T23:42:39.671+0000] {taskinstance.py:2905} ERROR - Task failed with exception
Traceback (most recent call last):
  File "/home/airflow/.local/lib/python3.12/site-packages/airflow/models/taskinstance.py", line 465, in _execute_task
    result = _execute_callable(context=context, **execute_callable_kwargs)
             ^^^^^^^^^^^^^^^^^^^^^^^^^^^^^^^^^^^^^^^^^^^^^^^^^^^^^^^^^^^^^
  File "/home/airflow/.local/lib/python3.12/site-packages/airflow/models/taskinstance.py", line 432, in _execute_callable
    return execute_callable(context=context, **execute_callable_kwargs)
           ^^^^^^^^^^^^^^^^^^^^^^^^^^^^^^^^^^^^^^^^^^^^^^^^^^^^^^^^^^^^
  File "/home/airflow/.local/lib/python3.12/site-packages/airflow/models/baseoperator.py", line 400, in wrapper
    return func(self, *args, **kwargs)
           ^^^^^^^^^^^^^^^^^^^^^^^^^^^
  File "/home/airflow/.local/lib/python3.12/site-packages/airflow/operators/bash.py", line 243, in execute
    raise AirflowException(
airflow.exceptions.AirflowException: Bash command failed. The command returned a non-zero exit code 127.
[2024-07-21T23:42:39.680+0000] {taskinstance.py:1206} INFO - Marking task as UP_FOR_RETRY. dag_id=our_first_dag, task_id=first_task, run_id=scheduled__2024-07-20T00:00:00+00:00, execution_date=20240720T000000, start_date=20240721T234239, end_date=20240721T234239
[2024-07-21T23:42:39.696+0000] {standard_task_runner.py:110} ERROR - Failed to execute job 15 for task first_task (Bash command failed. The command returned a non-zero exit code 127.; 372)
[2024-07-21T23:42:39.740+0000] {local_task_job_runner.py:240} INFO - Task exited with return code 1
[2024-07-21T23:42:39.753+0000] {local_task_job_runner.py:222} INFO - ::endgroup::
